{
 "cells": [
  {
   "cell_type": "code",
   "execution_count": null,
   "metadata": {},
   "outputs": [
    {
     "name": "stderr",
     "output_type": "stream",
     "text": [
      "Exception in thread Thread-34:\n",
      "Traceback (most recent call last):\n",
      "  File \"/usr/lib/python2.7/threading.py\", line 801, in __bootstrap_inner\n",
      "    self.run()\n",
      "  File \"/usr/lib/python2.7/threading.py\", line 754, in run\n",
      "    self.__target(*self.__args, **self.__kwargs)\n",
      "  File \"<ipython-input-1-a7b5dcdf2c63>\", line 43, in threader\n",
      "    get_data(m[0],m[1],m[2],m[3])\n",
      "  File \"<ipython-input-1-a7b5dcdf2c63>\", line 11, in get_data\n",
      "    urlData = requests.get(url).content\n",
      "  File \"/usr/local/lib/python2.7/dist-packages/requests/api.py\", line 72, in get\n",
      "    return request('get', url, params=params, **kwargs)\n",
      "  File \"/usr/local/lib/python2.7/dist-packages/requests/api.py\", line 58, in request\n",
      "    return session.request(method=method, url=url, **kwargs)\n",
      "  File \"/usr/local/lib/python2.7/dist-packages/requests/sessions.py\", line 508, in request\n",
      "    resp = self.send(prep, **send_kwargs)\n",
      "  File \"/usr/local/lib/python2.7/dist-packages/requests/sessions.py\", line 618, in send\n",
      "    r = adapter.send(request, **kwargs)\n",
      "  File \"/usr/local/lib/python2.7/dist-packages/requests/adapters.py\", line 508, in send\n",
      "    raise ConnectionError(e, request=request)\n",
      "ConnectionError: HTTPConnectionPool(host='weather.uwyo.edu', port=80): Max retries exceeded with url: /cgi-bin/sounding?region=naconf&TYPE=TEXT%3ALIST&YEAR=2007&MONTH=1&FROM=3100&TO=3100&STNM=16080 (Caused by NewConnectionError('<urllib3.connection.HTTPConnection object at 0x7f747c1cc210>: Failed to establish a new connection: [Errno -3] Temporary failure in name resolution',))\n",
      "Exception in thread Thread-47:\n",
      "Traceback (most recent call last):\n",
      "  File \"/usr/lib/python2.7/threading.py\", line 801, in __bootstrap_inner\n",
      "    self.run()\n",
      "  File \"/usr/lib/python2.7/threading.py\", line 754, in run\n",
      "    self.__target(*self.__args, **self.__kwargs)\n",
      "  File \"<ipython-input-1-a7b5dcdf2c63>\", line 43, in threader\n",
      "    get_data(m[0],m[1],m[2],m[3])\n",
      "  File \"<ipython-input-1-a7b5dcdf2c63>\", line 11, in get_data\n",
      "    urlData = requests.get(url).content\n",
      "  File \"/usr/local/lib/python2.7/dist-packages/requests/api.py\", line 72, in get\n",
      "    return request('get', url, params=params, **kwargs)\n",
      "  File \"/usr/local/lib/python2.7/dist-packages/requests/api.py\", line 58, in request\n",
      "    return session.request(method=method, url=url, **kwargs)\n",
      "  File \"/usr/local/lib/python2.7/dist-packages/requests/sessions.py\", line 508, in request\n",
      "    resp = self.send(prep, **send_kwargs)\n",
      "  File \"/usr/local/lib/python2.7/dist-packages/requests/sessions.py\", line 618, in send\n",
      "    r = adapter.send(request, **kwargs)\n",
      "  File \"/usr/local/lib/python2.7/dist-packages/requests/adapters.py\", line 508, in send\n",
      "    raise ConnectionError(e, request=request)\n",
      "ConnectionError: HTTPConnectionPool(host='weather.uwyo.edu', port=80): Max retries exceeded with url: /cgi-bin/sounding?region=naconf&TYPE=TEXT%3ALIST&YEAR=2007&MONTH=2&FROM=1300&TO=1300&STNM=16080 (Caused by NewConnectionError('<urllib3.connection.HTTPConnection object at 0x7f747c188b90>: Failed to establish a new connection: [Errno -3] Temporary failure in name resolution',))\n",
      "Exception in thread Thread-10:\n",
      "Traceback (most recent call last):\n",
      "  File \"/usr/lib/python2.7/threading.py\", line 801, in __bootstrap_inner\n",
      "    self.run()\n",
      "  File \"/usr/lib/python2.7/threading.py\", line 754, in run\n",
      "    self.__target(*self.__args, **self.__kwargs)\n",
      "  File \"<ipython-input-1-a7b5dcdf2c63>\", line 43, in threader\n",
      "    get_data(m[0],m[1],m[2],m[3])\n",
      "  File \"<ipython-input-1-a7b5dcdf2c63>\", line 11, in get_data\n",
      "    urlData = requests.get(url).content\n",
      "  File \"/usr/local/lib/python2.7/dist-packages/requests/api.py\", line 72, in get\n",
      "    return request('get', url, params=params, **kwargs)\n",
      "  File \"/usr/local/lib/python2.7/dist-packages/requests/api.py\", line 58, in request\n",
      "    return session.request(method=method, url=url, **kwargs)\n",
      "  File \"/usr/local/lib/python2.7/dist-packages/requests/sessions.py\", line 508, in request\n",
      "    resp = self.send(prep, **send_kwargs)\n",
      "  File \"/usr/local/lib/python2.7/dist-packages/requests/sessions.py\", line 618, in send\n",
      "    r = adapter.send(request, **kwargs)\n",
      "  File \"/usr/local/lib/python2.7/dist-packages/requests/adapters.py\", line 508, in send\n",
      "    raise ConnectionError(e, request=request)\n",
      "ConnectionError: HTTPConnectionPool(host='weather.uwyo.edu', port=80): Max retries exceeded with url: /cgi-bin/sounding?region=naconf&TYPE=TEXT%3ALIST&YEAR=2007&MONTH=1&FROM=700&TO=700&STNM=16080 (Caused by NewConnectionError('<urllib3.connection.HTTPConnection object at 0x7f749c0bd3d0>: Failed to establish a new connection: [Errno -3] Temporary failure in name resolution',))\n",
      "Exception in thread Thread-41:\n",
      "Traceback (most recent call last):\n",
      "  File \"/usr/lib/python2.7/threading.py\", line 801, in __bootstrap_inner\n",
      "    self.run()\n",
      "  File \"/usr/lib/python2.7/threading.py\", line 754, in run\n",
      "    self.__target(*self.__args, **self.__kwargs)\n",
      "  File \"<ipython-input-1-a7b5dcdf2c63>\", line 43, in threader\n",
      "    get_data(m[0],m[1],m[2],m[3])\n",
      "  File \"<ipython-input-1-a7b5dcdf2c63>\", line 11, in get_data\n",
      "    urlData = requests.get(url).content\n",
      "  File \"/usr/local/lib/python2.7/dist-packages/requests/api.py\", line 72, in get\n",
      "    return request('get', url, params=params, **kwargs)\n",
      "  File \"/usr/local/lib/python2.7/dist-packages/requests/api.py\", line 58, in request\n",
      "    return session.request(method=method, url=url, **kwargs)\n",
      "  File \"/usr/local/lib/python2.7/dist-packages/requests/sessions.py\", line 508, in request\n",
      "    resp = self.send(prep, **send_kwargs)\n",
      "  File \"/usr/local/lib/python2.7/dist-packages/requests/sessions.py\", line 618, in send\n",
      "    r = adapter.send(request, **kwargs)\n",
      "  File \"/usr/local/lib/python2.7/dist-packages/requests/adapters.py\", line 508, in send\n",
      "    raise ConnectionError(e, request=request)\n",
      "ConnectionError: HTTPConnectionPool(host='weather.uwyo.edu', port=80): Max retries exceeded with url: /cgi-bin/sounding?region=naconf&TYPE=TEXT%3ALIST&YEAR=2007&MONTH=2&FROM=700&TO=700&STNM=16080 (Caused by NewConnectionError('<urllib3.connection.HTTPConnection object at 0x7f747c174ad0>: Failed to establish a new connection: [Errno -3] Temporary failure in name resolution',))\n",
      "\n",
      "Exception in thread Thread-42:\n",
      "Traceback (most recent call last):\n",
      "  File \"/usr/lib/python2.7/threading.py\", line 801, in __bootstrap_inner\n",
      "    self.run()\n",
      "  File \"/usr/lib/python2.7/threading.py\", line 754, in run\n",
      "    self.__target(*self.__args, **self.__kwargs)\n",
      "  File \"<ipython-input-1-a7b5dcdf2c63>\", line 43, in threader\n",
      "    get_data(m[0],m[1],m[2],m[3])\n",
      "  File \"<ipython-input-1-a7b5dcdf2c63>\", line 11, in get_data\n",
      "    urlData = requests.get(url).content\n",
      "  File \"/usr/local/lib/python2.7/dist-packages/requests/api.py\", line 72, in get\n",
      "    return request('get', url, params=params, **kwargs)\n",
      "  File \"/usr/local/lib/python2.7/dist-packages/requests/api.py\", line 58, in request\n",
      "    return session.request(method=method, url=url, **kwargs)\n",
      "  File \"/usr/local/lib/python2.7/dist-packages/requests/sessions.py\", line 508, in request\n",
      "    resp = self.send(prep, **send_kwargs)\n",
      "  File \"/usr/local/lib/python2.7/dist-packages/requests/sessions.py\", line 618, in send\n",
      "    r = adapter.send(request, **kwargs)\n",
      "  File \"/usr/local/lib/python2.7/dist-packages/requests/adapters.py\", line 508, in send\n",
      "    raise ConnectionError(e, request=request)\n",
      "ConnectionError: HTTPConnectionPool(host='weather.uwyo.edu', port=80): Max retries exceeded with url: /cgi-bin/sounding?region=naconf&TYPE=TEXT%3ALIST&YEAR=2007&MONTH=4&FROM=1100&TO=1100&STNM=16080 (Caused by NewConnectionError('<urllib3.connection.HTTPConnection object at 0x7f747c1747d0>: Failed to establish a new connection: [Errno -3] Temporary failure in name resolution',))\n",
      "Exception in thread Thread-4:\n",
      "Traceback (most recent call last):\n",
      "  File \"/usr/lib/python2.7/threading.py\", line 801, in __bootstrap_inner\n",
      "    self.run()\n",
      "  File \"/usr/lib/python2.7/threading.py\", line 754, in run\n",
      "    self.__target(*self.__args, **self.__kwargs)\n",
      "  File \"<ipython-input-1-a7b5dcdf2c63>\", line 43, in threader\n",
      "    get_data(m[0],m[1],m[2],m[3])\n",
      "  File \"<ipython-input-1-a7b5dcdf2c63>\", line 11, in get_data\n",
      "    urlData = requests.get(url).content\n",
      "  File \"/usr/local/lib/python2.7/dist-packages/requests/api.py\", line 72, in get\n",
      "    return request('get', url, params=params, **kwargs)\n",
      "  File \"/usr/local/lib/python2.7/dist-packages/requests/api.py\", line 58, in request\n",
      "    return session.request(method=method, url=url, **kwargs)\n",
      "  File \"/usr/local/lib/python2.7/dist-packages/requests/sessions.py\", line 508, in request\n",
      "    resp = self.send(prep, **send_kwargs)\n",
      "  File \"/usr/local/lib/python2.7/dist-packages/requests/sessions.py\", line 618, in send\n",
      "    r = adapter.send(request, **kwargs)\n",
      "  File \"/usr/local/lib/python2.7/dist-packages/requests/adapters.py\", line 508, in send\n",
      "    raise ConnectionError(e, request=request)\n",
      "ConnectionError: HTTPConnectionPool(host='weather.uwyo.edu', port=80): Max retries exceeded with url: /cgi-bin/sounding?region=naconf&TYPE=TEXT%3ALIST&YEAR=2007&MONTH=1&FROM=100&TO=100&STNM=16080 (Caused by NewConnectionError('<urllib3.connection.HTTPConnection object at 0x7f749c0f4f90>: Failed to establish a new connection: [Errno -3] Temporary failure in name resolution',))\n",
      "Exception in thread Thread-44:\n",
      "Traceback (most recent call last):\n",
      "  File \"/usr/lib/python2.7/threading.py\", line 801, in __bootstrap_inner\n",
      "    self.run()\n",
      "  File \"/usr/lib/python2.7/threading.py\", line 754, in run\n",
      "    self.__target(*self.__args, **self.__kwargs)\n",
      "  File \"<ipython-input-1-a7b5dcdf2c63>\", line 43, in threader\n",
      "    get_data(m[0],m[1],m[2],m[3])\n",
      "  File \"<ipython-input-1-a7b5dcdf2c63>\", line 11, in get_data\n",
      "    urlData = requests.get(url).content\n",
      "  File \"/usr/local/lib/python2.7/dist-packages/requests/api.py\", line 72, in get\n",
      "    return request('get', url, params=params, **kwargs)\n",
      "  File \"/usr/local/lib/python2.7/dist-packages/requests/api.py\", line 58, in request\n",
      "    return session.request(method=method, url=url, **kwargs)\n",
      "  File \"/usr/local/lib/python2.7/dist-packages/requests/sessions.py\", line 508, in request\n",
      "    resp = self.send(prep, **send_kwargs)\n",
      "  File \"/usr/local/lib/python2.7/dist-packages/requests/sessions.py\", line 618, in send\n",
      "    r = adapter.send(request, **kwargs)\n",
      "  File \"/usr/local/lib/python2.7/dist-packages/requests/adapters.py\", line 508, in send\n",
      "    raise ConnectionError(e, request=request)\n",
      "ConnectionError: HTTPConnectionPool(host='weather.uwyo.edu', port=80): Max retries exceeded with url: /cgi-bin/sounding?region=naconf&TYPE=TEXT%3ALIST&YEAR=2007&MONTH=2&FROM=1000&TO=1000&STNM=16080 (Caused by NewConnectionError('<urllib3.connection.HTTPConnection object at 0x7f747c188a50>: Failed to establish a new connection: [Errno -3] Temporary failure in name resolution',))\n",
      "Exception in thread Thread-18:\n",
      "Traceback (most recent call last):\n",
      "  File \"/usr/lib/python2.7/threading.py\", line 801, in __bootstrap_inner\n",
      "    self.run()\n",
      "  File \"/usr/lib/python2.7/threading.py\", line 754, in run\n",
      "    self.__target(*self.__args, **self.__kwargs)\n",
      "  File \"<ipython-input-1-a7b5dcdf2c63>\", line 43, in threader\n",
      "    get_data(m[0],m[1],m[2],m[3])\n",
      "  File \"<ipython-input-1-a7b5dcdf2c63>\", line 11, in get_data\n",
      "    urlData = requests.get(url).content\n",
      "  File \"/usr/local/lib/python2.7/dist-packages/requests/api.py\", line 72, in get\n",
      "    return request('get', url, params=params, **kwargs)\n",
      "  File \"/usr/local/lib/python2.7/dist-packages/requests/api.py\", line 58, in request\n",
      "    return session.request(method=method, url=url, **kwargs)\n",
      "  File \"/usr/local/lib/python2.7/dist-packages/requests/sessions.py\", line 508, in request\n",
      "    resp = self.send(prep, **send_kwargs)\n",
      "  File \"/usr/local/lib/python2.7/dist-packages/requests/sessions.py\", line 618, in send\n",
      "    r = adapter.send(request, **kwargs)\n",
      "  File \"/usr/local/lib/python2.7/dist-packages/requests/adapters.py\", line 508, in send\n",
      "    raise ConnectionError(e, request=request)\n",
      "ConnectionError: HTTPConnectionPool(host='weather.uwyo.edu', port=80): Max retries exceeded with url: /cgi-bin/sounding?region=naconf&TYPE=TEXT%3ALIST&YEAR=2007&MONTH=4&FROM=1200&TO=1200&STNM=16080 (Caused by NewConnectionError('<urllib3.connection.HTTPConnection object at 0x7f749c0997d0>: Failed to establish a new connection: [Errno -3] Temporary failure in name resolution',))\n",
      "Exception in thread Thread-29:\n",
      "Traceback (most recent call last):\n",
      "  File \"/usr/lib/python2.7/threading.py\", line 801, in __bootstrap_inner\n",
      "    self.run()\n",
      "  File \"/usr/lib/python2.7/threading.py\", line 754, in run\n",
      "    self.__target(*self.__args, **self.__kwargs)\n",
      "  File \"<ipython-input-1-a7b5dcdf2c63>\", line 43, in threader\n",
      "    get_data(m[0],m[1],m[2],m[3])\n",
      "  File \"<ipython-input-1-a7b5dcdf2c63>\", line 11, in get_data\n",
      "    urlData = requests.get(url).content\n",
      "  File \"/usr/local/lib/python2.7/dist-packages/requests/api.py\", line 72, in get\n",
      "    return request('get', url, params=params, **kwargs)\n",
      "  File \"/usr/local/lib/python2.7/dist-packages/requests/api.py\", line 58, in request\n",
      "    return session.request(method=method, url=url, **kwargs)\n",
      "  File \"/usr/local/lib/python2.7/dist-packages/requests/sessions.py\", line 508, in request\n",
      "    resp = self.send(prep, **send_kwargs)\n",
      "  File \"/usr/local/lib/python2.7/dist-packages/requests/sessions.py\", line 618, in send\n",
      "    r = adapter.send(request, **kwargs)\n",
      "  File \"/usr/local/lib/python2.7/dist-packages/requests/adapters.py\", line 508, in send\n",
      "    raise ConnectionError(e, request=request)\n",
      "ConnectionError: HTTPConnectionPool(host='weather.uwyo.edu', port=80): Max retries exceeded with url: /cgi-bin/sounding?region=naconf&TYPE=TEXT%3ALIST&YEAR=2007&MONTH=1&FROM=2500&TO=2500&STNM=16080 (Caused by NewConnectionError('<urllib3.connection.HTTPConnection object at 0x7f749c027490>: Failed to establish a new connection: [Errno -3] Temporary failure in name resolution',))\n",
      "Exception in thread Thread-49:\n",
      "Traceback (most recent call last):\n",
      "  File \"/usr/lib/python2.7/threading.py\", line 801, in __bootstrap_inner\n",
      "    self.run()\n",
      "  File \"/usr/lib/python2.7/threading.py\", line 754, in run\n",
      "    self.__target(*self.__args, **self.__kwargs)\n",
      "  File \"<ipython-input-1-a7b5dcdf2c63>\", line 43, in threader\n",
      "    get_data(m[0],m[1],m[2],m[3])\n",
      "  File \"<ipython-input-1-a7b5dcdf2c63>\", line 11, in get_data\n",
      "    urlData = requests.get(url).content\n",
      "  File \"/usr/local/lib/python2.7/dist-packages/requests/api.py\", line 72, in get\n",
      "    return request('get', url, params=params, **kwargs)\n",
      "  File \"/usr/local/lib/python2.7/dist-packages/requests/api.py\", line 58, in request\n",
      "    return session.request(method=method, url=url, **kwargs)\n",
      "  File \"/usr/local/lib/python2.7/dist-packages/requests/sessions.py\", line 508, in request\n",
      "    resp = self.send(prep, **send_kwargs)\n",
      "  File \"/usr/local/lib/python2.7/dist-packages/requests/sessions.py\", line 618, in send\n",
      "    r = adapter.send(request, **kwargs)\n",
      "  File \"/usr/local/lib/python2.7/dist-packages/requests/adapters.py\", line 508, in send\n",
      "    raise ConnectionError(e, request=request)\n",
      "ConnectionError: HTTPConnectionPool(host='weather.uwyo.edu', port=80): Max retries exceeded with url: /cgi-bin/sounding?region=naconf&TYPE=TEXT%3ALIST&YEAR=2007&MONTH=2&FROM=1500&TO=1500&STNM=16080 (Caused by NewConnectionError('<urllib3.connection.HTTPConnection object at 0x7f747c12c750>: Failed to establish a new connection: [Errno -3] Temporary failure in name resolution',))\n",
      "Exception in thread Thread-11:\n",
      "Traceback (most recent call last):\n",
      "  File \"/usr/lib/python2.7/threading.py\", line 801, in __bootstrap_inner\n",
      "    self.run()\n",
      "  File \"/usr/lib/python2.7/threading.py\", line 754, in run\n",
      "    self.__target(*self.__args, **self.__kwargs)\n",
      "  File \"<ipython-input-1-a7b5dcdf2c63>\", line 43, in threader\n",
      "    get_data(m[0],m[1],m[2],m[3])\n",
      "  File \"<ipython-input-1-a7b5dcdf2c63>\", line 11, in get_data\n",
      "    urlData = requests.get(url).content\n",
      "  File \"/usr/local/lib/python2.7/dist-packages/requests/api.py\", line 72, in get\n",
      "    return request('get', url, params=params, **kwargs)\n",
      "  File \"/usr/local/lib/python2.7/dist-packages/requests/api.py\", line 58, in request\n",
      "    return session.request(method=method, url=url, **kwargs)\n",
      "  File \"/usr/local/lib/python2.7/dist-packages/requests/sessions.py\", line 508, in request\n",
      "    resp = self.send(prep, **send_kwargs)\n",
      "  File \"/usr/local/lib/python2.7/dist-packages/requests/sessions.py\", line 618, in send\n",
      "    r = adapter.send(request, **kwargs)\n",
      "  File \"/usr/local/lib/python2.7/dist-packages/requests/adapters.py\", line 508, in send\n",
      "    raise ConnectionError(e, request=request)\n",
      "ConnectionError: HTTPConnectionPool(host='weather.uwyo.edu', port=80): Max retries exceeded with url: /cgi-bin/sounding?region=naconf&TYPE=TEXT%3ALIST&YEAR=2007&MONTH=1&FROM=800&TO=800&STNM=16080 (Caused by NewConnectionError('<urllib3.connection.HTTPConnection object at 0x7f749c099a10>: Failed to establish a new connection: [Errno -3] Temporary failure in name resolution',))\n",
      "Exception in thread Thread-23:\n",
      "Traceback (most recent call last):\n",
      "  File \"/usr/lib/python2.7/threading.py\", line 801, in __bootstrap_inner\n",
      "    self.run()\n",
      "  File \"/usr/lib/python2.7/threading.py\", line 754, in run\n",
      "    self.__target(*self.__args, **self.__kwargs)\n",
      "  File \"<ipython-input-1-a7b5dcdf2c63>\", line 43, in threader\n",
      "    get_data(m[0],m[1],m[2],m[3])\n",
      "  File \"<ipython-input-1-a7b5dcdf2c63>\", line 11, in get_data\n",
      "    urlData = requests.get(url).content\n",
      "  File \"/usr/local/lib/python2.7/dist-packages/requests/api.py\", line 72, in get\n",
      "    return request('get', url, params=params, **kwargs)\n",
      "  File \"/usr/local/lib/python2.7/dist-packages/requests/api.py\", line 58, in request\n",
      "    return session.request(method=method, url=url, **kwargs)\n",
      "  File \"/usr/local/lib/python2.7/dist-packages/requests/sessions.py\", line 508, in request\n",
      "    resp = self.send(prep, **send_kwargs)\n",
      "  File \"/usr/local/lib/python2.7/dist-packages/requests/sessions.py\", line 618, in send\n",
      "    r = adapter.send(request, **kwargs)\n",
      "  File \"/usr/local/lib/python2.7/dist-packages/requests/adapters.py\", line 508, in send\n",
      "    raise ConnectionError(e, request=request)\n",
      "ConnectionError: HTTPConnectionPool(host='weather.uwyo.edu', port=80): Max retries exceeded with url: /cgi-bin/sounding?region=naconf&TYPE=TEXT%3ALIST&YEAR=2007&MONTH=4&FROM=1300&TO=1300&STNM=16080 (Caused by NewConnectionError('<urllib3.connection.HTTPConnection object at 0x7f749c084f90>: Failed to establish a new connection: [Errno -3] Temporary failure in name resolution',))\n",
      "Exception in thread Thread-43:\n",
      "Traceback (most recent call last):\n",
      "  File \"/usr/lib/python2.7/threading.py\", line 801, in __bootstrap_inner\n",
      "    self.run()\n",
      "  File \"/usr/lib/python2.7/threading.py\", line 754, in run\n",
      "    self.__target(*self.__args, **self.__kwargs)\n",
      "  File \"<ipython-input-1-a7b5dcdf2c63>\", line 43, in threader\n",
      "    get_data(m[0],m[1],m[2],m[3])\n",
      "  File \"<ipython-input-1-a7b5dcdf2c63>\", line 11, in get_data\n",
      "    urlData = requests.get(url).content\n",
      "  File \"/usr/local/lib/python2.7/dist-packages/requests/api.py\", line 72, in get\n",
      "    return request('get', url, params=params, **kwargs)\n",
      "  File \"/usr/local/lib/python2.7/dist-packages/requests/api.py\", line 58, in request\n",
      "    return session.request(method=method, url=url, **kwargs)\n",
      "  File \"/usr/local/lib/python2.7/dist-packages/requests/sessions.py\", line 508, in request\n",
      "    resp = self.send(prep, **send_kwargs)\n",
      "  File \"/usr/local/lib/python2.7/dist-packages/requests/sessions.py\", line 618, in send\n",
      "    r = adapter.send(request, **kwargs)\n",
      "  File \"/usr/local/lib/python2.7/dist-packages/requests/adapters.py\", line 508, in send\n",
      "    raise ConnectionError(e, request=request)\n",
      "ConnectionError: HTTPConnectionPool(host='weather.uwyo.edu', port=80): Max retries exceeded with url: /cgi-bin/sounding?region=naconf&TYPE=TEXT%3ALIST&YEAR=2007&MONTH=4&FROM=900&TO=900&STNM=16080 (Caused by NewConnectionError('<urllib3.connection.HTTPConnection object at 0x7f747c12cfd0>: Failed to establish a new connection: [Errno -3] Temporary failure in name resolution',))\n",
      "Exception in thread Thread-48:\n",
      "Traceback (most recent call last):\n",
      "  File \"/usr/lib/python2.7/threading.py\", line 801, in __bootstrap_inner\n",
      "    self.run()\n",
      "  File \"/usr/lib/python2.7/threading.py\", line 754, in run\n",
      "    self.__target(*self.__args, **self.__kwargs)\n",
      "  File \"<ipython-input-1-a7b5dcdf2c63>\", line 43, in threader\n",
      "    get_data(m[0],m[1],m[2],m[3])\n",
      "  File \"<ipython-input-1-a7b5dcdf2c63>\", line 11, in get_data\n",
      "    urlData = requests.get(url).content\n",
      "  File \"/usr/local/lib/python2.7/dist-packages/requests/api.py\", line 72, in get\n",
      "    return request('get', url, params=params, **kwargs)\n",
      "  File \"/usr/local/lib/python2.7/dist-packages/requests/api.py\", line 58, in request\n",
      "    return session.request(method=method, url=url, **kwargs)\n",
      "  File \"/usr/local/lib/python2.7/dist-packages/requests/sessions.py\", line 508, in request\n",
      "    resp = self.send(prep, **send_kwargs)\n",
      "  File \"/usr/local/lib/python2.7/dist-packages/requests/sessions.py\", line 618, in send\n",
      "    r = adapter.send(request, **kwargs)\n",
      "  File \"/usr/local/lib/python2.7/dist-packages/requests/adapters.py\", line 508, in send\n",
      "    raise ConnectionError(e, request=request)\n",
      "ConnectionError: HTTPConnectionPool(host='weather.uwyo.edu', port=80): Max retries exceeded with url: /cgi-bin/sounding?region=naconf&TYPE=TEXT%3ALIST&YEAR=2007&MONTH=2&FROM=1400&TO=1400&STNM=16080 (Caused by NewConnectionError('<urllib3.connection.HTTPConnection object at 0x7f747c12c890>: Failed to establish a new connection: [Errno -3] Temporary failure in name resolution',))\n",
      "\n",
      "\n",
      "\n",
      "\n",
      "\n",
      "\n",
      "\n",
      "\n",
      "\n",
      "\n",
      "\n",
      "\n",
      "\n"
     ]
    },
    {
     "name": "stderr",
     "output_type": "stream",
     "text": [
      "Exception in thread Thread-31:\n",
      "Traceback (most recent call last):\n",
      "  File \"/usr/lib/python2.7/threading.py\", line 801, in __bootstrap_inner\n",
      "    self.run()\n",
      "  File \"/usr/lib/python2.7/threading.py\", line 754, in run\n",
      "    self.__target(*self.__args, **self.__kwargs)\n",
      "  File \"<ipython-input-1-a7b5dcdf2c63>\", line 43, in threader\n",
      "    get_data(m[0],m[1],m[2],m[3])\n",
      "  File \"<ipython-input-1-a7b5dcdf2c63>\", line 11, in get_data\n",
      "    urlData = requests.get(url).content\n",
      "  File \"/usr/local/lib/python2.7/dist-packages/requests/api.py\", line 72, in get\n",
      "    return request('get', url, params=params, **kwargs)\n",
      "  File \"/usr/local/lib/python2.7/dist-packages/requests/api.py\", line 58, in request\n",
      "    return session.request(method=method, url=url, **kwargs)\n",
      "  File \"/usr/local/lib/python2.7/dist-packages/requests/sessions.py\", line 508, in request\n",
      "    resp = self.send(prep, **send_kwargs)\n",
      "  File \"/usr/local/lib/python2.7/dist-packages/requests/sessions.py\", line 618, in send\n",
      "    r = adapter.send(request, **kwargs)\n",
      "  File \"/usr/local/lib/python2.7/dist-packages/requests/adapters.py\", line 508, in send\n",
      "    raise ConnectionError(e, request=request)\n",
      "ConnectionError: HTTPConnectionPool(host='weather.uwyo.edu', port=80): Max retries exceeded with url: /cgi-bin/sounding?region=naconf&TYPE=TEXT%3ALIST&YEAR=2007&MONTH=4&FROM=2800&TO=2800&STNM=16080 (Caused by NewConnectionError('<urllib3.connection.HTTPConnection object at 0x7f749c076650>: Failed to establish a new connection: [Errno -3] Temporary failure in name resolution',))\n",
      "\n",
      "Exception in thread Thread-17:\n",
      "Traceback (most recent call last):\n",
      "  File \"/usr/lib/python2.7/threading.py\", line 801, in __bootstrap_inner\n",
      "    self.run()\n",
      "  File \"/usr/lib/python2.7/threading.py\", line 754, in run\n",
      "    self.__target(*self.__args, **self.__kwargs)\n",
      "  File \"<ipython-input-1-a7b5dcdf2c63>\", line 43, in threader\n",
      "    get_data(m[0],m[1],m[2],m[3])\n",
      "  File \"<ipython-input-1-a7b5dcdf2c63>\", line 11, in get_data\n",
      "    urlData = requests.get(url).content\n",
      "  File \"/usr/local/lib/python2.7/dist-packages/requests/api.py\", line 72, in get\n",
      "    return request('get', url, params=params, **kwargs)\n",
      "  File \"/usr/local/lib/python2.7/dist-packages/requests/api.py\", line 58, in request\n",
      "    return session.request(method=method, url=url, **kwargs)\n",
      "  File \"/usr/local/lib/python2.7/dist-packages/requests/sessions.py\", line 508, in request\n",
      "    resp = self.send(prep, **send_kwargs)\n",
      "  File \"/usr/local/lib/python2.7/dist-packages/requests/sessions.py\", line 618, in send\n",
      "    r = adapter.send(request, **kwargs)\n",
      "  File \"/usr/local/lib/python2.7/dist-packages/requests/adapters.py\", line 508, in send\n",
      "    raise ConnectionError(e, request=request)\n",
      "ConnectionError: HTTPConnectionPool(host='weather.uwyo.edu', port=80): Max retries exceeded with url: /cgi-bin/sounding?region=naconf&TYPE=TEXT%3ALIST&YEAR=2007&MONTH=4&FROM=3100&TO=3100&STNM=16080 (Caused by NewConnectionError('<urllib3.connection.HTTPConnection object at 0x7f749c099ad0>: Failed to establish a new connection: [Errno -3] Temporary failure in name resolution',))\n",
      "\n",
      "Exception in thread Thread-33:\n",
      "Traceback (most recent call last):\n",
      "  File \"/usr/lib/python2.7/threading.py\", line 801, in __bootstrap_inner\n",
      "    self.run()\n",
      "  File \"/usr/lib/python2.7/threading.py\", line 754, in run\n",
      "    self.__target(*self.__args, **self.__kwargs)\n",
      "  File \"<ipython-input-1-a7b5dcdf2c63>\", line 43, in threader\n",
      "    get_data(m[0],m[1],m[2],m[3])\n",
      "  File \"<ipython-input-1-a7b5dcdf2c63>\", line 11, in get_data\n",
      "    urlData = requests.get(url).content\n",
      "  File \"/usr/local/lib/python2.7/dist-packages/requests/api.py\", line 72, in get\n",
      "    return request('get', url, params=params, **kwargs)\n",
      "  File \"/usr/local/lib/python2.7/dist-packages/requests/api.py\", line 58, in request\n",
      "    return session.request(method=method, url=url, **kwargs)\n",
      "  File \"/usr/local/lib/python2.7/dist-packages/requests/sessions.py\", line 508, in request\n",
      "    resp = self.send(prep, **send_kwargs)\n",
      "  File \"/usr/local/lib/python2.7/dist-packages/requests/sessions.py\", line 618, in send\n",
      "    r = adapter.send(request, **kwargs)\n",
      "  File \"/usr/local/lib/python2.7/dist-packages/requests/adapters.py\", line 508, in send\n",
      "    raise ConnectionError(e, request=request)\n",
      "ConnectionError: HTTPConnectionPool(host='weather.uwyo.edu', port=80): Max retries exceeded with url: /cgi-bin/sounding?region=naconf&TYPE=TEXT%3ALIST&YEAR=2007&MONTH=5&FROM=2600&TO=2600&STNM=16080 (Caused by NewConnectionError('<urllib3.connection.HTTPConnection object at 0x7f749c0f4250>: Failed to establish a new connection: [Errno -3] Temporary failure in name resolution',))\n",
      "\n",
      "Exception in thread Thread-51:\n",
      "Traceback (most recent call last):\n",
      "  File \"/usr/lib/python2.7/threading.py\", line 801, in __bootstrap_inner\n",
      "    self.run()\n",
      "  File \"/usr/lib/python2.7/threading.py\", line 754, in run\n",
      "    self.__target(*self.__args, **self.__kwargs)\n",
      "  File \"<ipython-input-1-a7b5dcdf2c63>\", line 43, in threader\n",
      "    get_data(m[0],m[1],m[2],m[3])\n",
      "  File \"<ipython-input-1-a7b5dcdf2c63>\", line 11, in get_data\n",
      "    urlData = requests.get(url).content\n",
      "  File \"/usr/local/lib/python2.7/dist-packages/requests/api.py\", line 72, in get\n",
      "    return request('get', url, params=params, **kwargs)\n",
      "  File \"/usr/local/lib/python2.7/dist-packages/requests/api.py\", line 58, in request\n",
      "    return session.request(method=method, url=url, **kwargs)\n",
      "  File \"/usr/local/lib/python2.7/dist-packages/requests/sessions.py\", line 508, in request\n",
      "    resp = self.send(prep, **send_kwargs)\n",
      "  File \"/usr/local/lib/python2.7/dist-packages/requests/sessions.py\", line 618, in send\n",
      "    r = adapter.send(request, **kwargs)\n",
      "  File \"/usr/local/lib/python2.7/dist-packages/requests/adapters.py\", line 508, in send\n",
      "    raise ConnectionError(e, request=request)\n",
      "ConnectionError: HTTPConnectionPool(host='weather.uwyo.edu', port=80): Max retries exceeded with url: /cgi-bin/sounding?region=naconf&TYPE=TEXT%3ALIST&YEAR=2007&MONTH=5&FROM=2400&TO=2400&STNM=16080 (Caused by NewConnectionError('<urllib3.connection.HTTPConnection object at 0x7f749c11bf10>: Failed to establish a new connection: [Errno -3] Temporary failure in name resolution',))\n",
      "Exception in thread Thread-12:\n",
      "Traceback (most recent call last):\n",
      "  File \"/usr/lib/python2.7/threading.py\", line 801, in __bootstrap_inner\n",
      "    self.run()\n",
      "  File \"/usr/lib/python2.7/threading.py\", line 754, in run\n",
      "    self.__target(*self.__args, **self.__kwargs)\n",
      "  File \"<ipython-input-1-a7b5dcdf2c63>\", line 43, in threader\n",
      "    get_data(m[0],m[1],m[2],m[3])\n",
      "  File \"<ipython-input-1-a7b5dcdf2c63>\", line 11, in get_data\n",
      "    urlData = requests.get(url).content\n",
      "  File \"/usr/local/lib/python2.7/dist-packages/requests/api.py\", line 72, in get\n",
      "    return request('get', url, params=params, **kwargs)\n",
      "  File \"/usr/local/lib/python2.7/dist-packages/requests/api.py\", line 58, in request\n",
      "    return session.request(method=method, url=url, **kwargs)\n",
      "  File \"/usr/local/lib/python2.7/dist-packages/requests/sessions.py\", line 508, in request\n",
      "    resp = self.send(prep, **send_kwargs)\n",
      "  File \"/usr/local/lib/python2.7/dist-packages/requests/sessions.py\", line 618, in send\n",
      "    r = adapter.send(request, **kwargs)\n",
      "  File \"/usr/local/lib/python2.7/dist-packages/requests/adapters.py\", line 508, in send\n",
      "    raise ConnectionError(e, request=request)\n",
      "ConnectionError: HTTPConnectionPool(host='weather.uwyo.edu', port=80): Max retries exceeded with url: /cgi-bin/sounding?region=naconf&TYPE=TEXT%3ALIST&YEAR=2007&MONTH=5&FROM=2300&TO=2300&STNM=16080 (Caused by NewConnectionError('<urllib3.connection.HTTPConnection object at 0x7f749c0abad0>: Failed to establish a new connection: [Errno -3] Temporary failure in name resolution',))\n",
      "\n",
      "\n",
      "Exception in thread Thread-45:\n",
      "Traceback (most recent call last):\n",
      "  File \"/usr/lib/python2.7/threading.py\", line 801, in __bootstrap_inner\n",
      "    self.run()\n",
      "  File \"/usr/lib/python2.7/threading.py\", line 754, in run\n",
      "    self.__target(*self.__args, **self.__kwargs)\n",
      "  File \"<ipython-input-1-a7b5dcdf2c63>\", line 43, in threader\n",
      "    get_data(m[0],m[1],m[2],m[3])\n",
      "  File \"<ipython-input-1-a7b5dcdf2c63>\", line 11, in get_data\n",
      "    urlData = requests.get(url).content\n",
      "  File \"/usr/local/lib/python2.7/dist-packages/requests/api.py\", line 72, in get\n",
      "    return request('get', url, params=params, **kwargs)\n",
      "  File \"/usr/local/lib/python2.7/dist-packages/requests/api.py\", line 58, in request\n",
      "    return session.request(method=method, url=url, **kwargs)\n",
      "  File \"/usr/local/lib/python2.7/dist-packages/requests/sessions.py\", line 508, in request\n",
      "    resp = self.send(prep, **send_kwargs)\n",
      "  File \"/usr/local/lib/python2.7/dist-packages/requests/sessions.py\", line 618, in send\n",
      "    r = adapter.send(request, **kwargs)\n",
      "  File \"/usr/local/lib/python2.7/dist-packages/requests/adapters.py\", line 508, in send\n",
      "    raise ConnectionError(e, request=request)\n",
      "ConnectionError: HTTPConnectionPool(host='weather.uwyo.edu', port=80): Max retries exceeded with url: /cgi-bin/sounding?region=naconf&TYPE=TEXT%3ALIST&YEAR=2007&MONTH=3&FROM=1300&TO=1300&STNM=16080 (Caused by NewConnectionError('<urllib3.connection.HTTPConnection object at 0x7f747c15f610>: Failed to establish a new connection: [Errno -3] Temporary failure in name resolution',))\n",
      "\n",
      "Exception in thread Thread-30:\n",
      "Traceback (most recent call last):\n",
      "  File \"/usr/lib/python2.7/threading.py\", line 801, in __bootstrap_inner\n",
      "    self.run()\n",
      "  File \"/usr/lib/python2.7/threading.py\", line 754, in run\n",
      "    self.__target(*self.__args, **self.__kwargs)\n",
      "  File \"<ipython-input-1-a7b5dcdf2c63>\", line 43, in threader\n",
      "    get_data(m[0],m[1],m[2],m[3])\n",
      "  File \"<ipython-input-1-a7b5dcdf2c63>\", line 11, in get_data\n",
      "    urlData = requests.get(url).content\n",
      "  File \"/usr/local/lib/python2.7/dist-packages/requests/api.py\", line 72, in get\n",
      "    return request('get', url, params=params, **kwargs)\n",
      "  File \"/usr/local/lib/python2.7/dist-packages/requests/api.py\", line 58, in request\n",
      "    return session.request(method=method, url=url, **kwargs)\n",
      "  File \"/usr/local/lib/python2.7/dist-packages/requests/sessions.py\", line 508, in request\n",
      "    resp = self.send(prep, **send_kwargs)\n",
      "  File \"/usr/local/lib/python2.7/dist-packages/requests/sessions.py\", line 618, in send\n",
      "    r = adapter.send(request, **kwargs)\n",
      "  File \"/usr/local/lib/python2.7/dist-packages/requests/adapters.py\", line 508, in send\n",
      "    raise ConnectionError(e, request=request)\n",
      "ConnectionError: HTTPConnectionPool(host='weather.uwyo.edu', port=80): Max retries exceeded with url: /cgi-bin/sounding?region=naconf&TYPE=TEXT%3ALIST&YEAR=2007&MONTH=6&FROM=2900&TO=2900&STNM=16080 (Caused by NewConnectionError('<urllib3.connection.HTTPConnection object at 0x7f749c05fb10>: Failed to establish a new connection: [Errno -3] Temporary failure in name resolution',))\n",
      "\n",
      "Exception in thread Thread-35:\n",
      "Traceback (most recent call last):\n",
      "  File \"/usr/lib/python2.7/threading.py\", line 801, in __bootstrap_inner\n",
      "    self.run()\n",
      "  File \"/usr/lib/python2.7/threading.py\", line 754, in run\n",
      "    self.__target(*self.__args, **self.__kwargs)\n",
      "  File \"<ipython-input-1-a7b5dcdf2c63>\", line 43, in threader\n",
      "    get_data(m[0],m[1],m[2],m[3])\n",
      "  File \"<ipython-input-1-a7b5dcdf2c63>\", line 11, in get_data\n",
      "    urlData = requests.get(url).content\n",
      "  File \"/usr/local/lib/python2.7/dist-packages/requests/api.py\", line 72, in get\n",
      "    return request('get', url, params=params, **kwargs)\n",
      "  File \"/usr/local/lib/python2.7/dist-packages/requests/api.py\", line 58, in request\n",
      "    return session.request(method=method, url=url, **kwargs)\n",
      "  File \"/usr/local/lib/python2.7/dist-packages/requests/sessions.py\", line 508, in request\n",
      "    resp = self.send(prep, **send_kwargs)\n",
      "  File \"/usr/local/lib/python2.7/dist-packages/requests/sessions.py\", line 618, in send\n",
      "    r = adapter.send(request, **kwargs)\n",
      "  File \"/usr/local/lib/python2.7/dist-packages/requests/adapters.py\", line 508, in send\n",
      "    raise ConnectionError(e, request=request)\n",
      "ConnectionError: HTTPConnectionPool(host='weather.uwyo.edu', port=80): Max retries exceeded with url: /cgi-bin/sounding?region=naconf&TYPE=TEXT%3ALIST&YEAR=2007&MONTH=7&FROM=400&TO=400&STNM=16080 (Caused by NewConnectionError('<urllib3.connection.HTTPConnection object at 0x7f749c05fb90>: Failed to establish a new connection: [Errno -3] Temporary failure in name resolution',))\n",
      "\n",
      "Exception in thread Thread-28:\n",
      "Traceback (most recent call last):\n",
      "  File \"/usr/lib/python2.7/threading.py\", line 801, in __bootstrap_inner\n",
      "    self.run()\n",
      "  File \"/usr/lib/python2.7/threading.py\", line 754, in run\n",
      "    self.__target(*self.__args, **self.__kwargs)\n",
      "  File \"<ipython-input-1-a7b5dcdf2c63>\", line 43, in threader\n",
      "    get_data(m[0],m[1],m[2],m[3])\n",
      "  File \"<ipython-input-1-a7b5dcdf2c63>\", line 11, in get_data\n",
      "    urlData = requests.get(url).content\n",
      "  File \"/usr/local/lib/python2.7/dist-packages/requests/api.py\", line 72, in get\n",
      "    return request('get', url, params=params, **kwargs)\n",
      "  File \"/usr/local/lib/python2.7/dist-packages/requests/api.py\", line 58, in request\n",
      "    return session.request(method=method, url=url, **kwargs)\n",
      "  File \"/usr/local/lib/python2.7/dist-packages/requests/sessions.py\", line 508, in request\n",
      "    resp = self.send(prep, **send_kwargs)\n",
      "  File \"/usr/local/lib/python2.7/dist-packages/requests/sessions.py\", line 618, in send\n",
      "    r = adapter.send(request, **kwargs)\n",
      "  File \"/usr/local/lib/python2.7/dist-packages/requests/adapters.py\", line 508, in send\n",
      "    raise ConnectionError(e, request=request)\n",
      "ConnectionError: HTTPConnectionPool(host='weather.uwyo.edu', port=80): Max retries exceeded with url: /cgi-bin/sounding?region=naconf&TYPE=TEXT%3ALIST&YEAR=2007&MONTH=6&FROM=400&TO=400&STNM=16080 (Caused by NewConnectionError('<urllib3.connection.HTTPConnection object at 0x7f747c1bd150>: Failed to establish a new connection: [Errno -3] Temporary failure in name resolution',))\n",
      "\n",
      "Exception in thread Thread-16:\n",
      "Traceback (most recent call last):\n",
      "  File \"/usr/lib/python2.7/threading.py\", line 801, in __bootstrap_inner\n",
      "    self.run()\n",
      "  File \"/usr/lib/python2.7/threading.py\", line 754, in run\n",
      "    self.__target(*self.__args, **self.__kwargs)\n",
      "  File \"<ipython-input-1-a7b5dcdf2c63>\", line 43, in threader\n",
      "    get_data(m[0],m[1],m[2],m[3])\n",
      "  File \"<ipython-input-1-a7b5dcdf2c63>\", line 11, in get_data\n",
      "    urlData = requests.get(url).content\n",
      "  File \"/usr/local/lib/python2.7/dist-packages/requests/api.py\", line 72, in get\n",
      "    return request('get', url, params=params, **kwargs)\n",
      "  File \"/usr/local/lib/python2.7/dist-packages/requests/api.py\", line 58, in request\n",
      "    return session.request(method=method, url=url, **kwargs)\n",
      "  File \"/usr/local/lib/python2.7/dist-packages/requests/sessions.py\", line 508, in request\n",
      "    resp = self.send(prep, **send_kwargs)\n",
      "  File \"/usr/local/lib/python2.7/dist-packages/requests/sessions.py\", line 618, in send\n",
      "    r = adapter.send(request, **kwargs)\n",
      "  File \"/usr/local/lib/python2.7/dist-packages/requests/adapters.py\", line 508, in send\n",
      "    raise ConnectionError(e, request=request)\n",
      "ConnectionError: HTTPConnectionPool(host='weather.uwyo.edu', port=80): Max retries exceeded with url: /cgi-bin/sounding?region=naconf&TYPE=TEXT%3ALIST&YEAR=2007&MONTH=7&FROM=300&TO=300&STNM=16080 (Caused by NewConnectionError('<urllib3.connection.HTTPConnection object at 0x7f747c111690>: Failed to establish a new connection: [Errno -3] Temporary failure in name resolution',))\n",
      "\n",
      "Exception in thread Thread-53:\n",
      "Traceback (most recent call last):\n",
      "  File \"/usr/lib/python2.7/threading.py\", line 801, in __bootstrap_inner\n",
      "    self.run()\n",
      "  File \"/usr/lib/python2.7/threading.py\", line 754, in run\n",
      "    self.__target(*self.__args, **self.__kwargs)\n",
      "  File \"<ipython-input-1-a7b5dcdf2c63>\", line 43, in threader\n",
      "    get_data(m[0],m[1],m[2],m[3])\n",
      "  File \"<ipython-input-1-a7b5dcdf2c63>\", line 11, in get_data\n",
      "    urlData = requests.get(url).content\n",
      "  File \"/usr/local/lib/python2.7/dist-packages/requests/api.py\", line 72, in get\n",
      "    return request('get', url, params=params, **kwargs)\n",
      "  File \"/usr/local/lib/python2.7/dist-packages/requests/api.py\", line 58, in request\n",
      "    return session.request(method=method, url=url, **kwargs)\n",
      "  File \"/usr/local/lib/python2.7/dist-packages/requests/sessions.py\", line 508, in request\n",
      "    resp = self.send(prep, **send_kwargs)\n",
      "  File \"/usr/local/lib/python2.7/dist-packages/requests/sessions.py\", line 618, in send\n",
      "    r = adapter.send(request, **kwargs)\n",
      "  File \"/usr/local/lib/python2.7/dist-packages/requests/adapters.py\", line 508, in send\n",
      "    raise ConnectionError(e, request=request)\n",
      "ConnectionError: HTTPConnectionPool(host='weather.uwyo.edu', port=80): Max retries exceeded with url: /cgi-bin/sounding?region=naconf&TYPE=TEXT%3ALIST&YEAR=2007&MONTH=6&FROM=2700&TO=2700&STNM=16080 (Caused by NewConnectionError('<urllib3.connection.HTTPConnection object at 0x7f749f333810>: Failed to establish a new connection: [Errno -3] Temporary failure in name resolution',))\n",
      "\n",
      "Exception in thread Thread-39:\n",
      "Traceback (most recent call last):\n",
      "  File \"/usr/lib/python2.7/threading.py\", line 801, in __bootstrap_inner\n",
      "    self.run()\n",
      "  File \"/usr/lib/python2.7/threading.py\", line 754, in run\n",
      "    self.__target(*self.__args, **self.__kwargs)\n",
      "  File \"<ipython-input-1-a7b5dcdf2c63>\", line 43, in threader\n",
      "    get_data(m[0],m[1],m[2],m[3])\n",
      "  File \"<ipython-input-1-a7b5dcdf2c63>\", line 11, in get_data\n",
      "    urlData = requests.get(url).content\n",
      "  File \"/usr/local/lib/python2.7/dist-packages/requests/api.py\", line 72, in get\n",
      "    return request('get', url, params=params, **kwargs)\n",
      "  File \"/usr/local/lib/python2.7/dist-packages/requests/api.py\", line 58, in request\n",
      "    return session.request(method=method, url=url, **kwargs)\n",
      "  File \"/usr/local/lib/python2.7/dist-packages/requests/sessions.py\", line 508, in request\n",
      "    resp = self.send(prep, **send_kwargs)\n",
      "  File \"/usr/local/lib/python2.7/dist-packages/requests/sessions.py\", line 618, in send\n",
      "    r = adapter.send(request, **kwargs)\n",
      "  File \"/usr/local/lib/python2.7/dist-packages/requests/adapters.py\", line 508, in send\n",
      "    raise ConnectionError(e, request=request)\n",
      "ConnectionError: HTTPConnectionPool(host='weather.uwyo.edu', port=80): Max retries exceeded with url: /cgi-bin/sounding?region=naconf&TYPE=TEXT%3ALIST&YEAR=2007&MONTH=6&FROM=2500&TO=2500&STNM=16080 (Caused by NewConnectionError('<urllib3.connection.HTTPConnection object at 0x7f749c05ffd0>: Failed to establish a new connection: [Errno -3] Temporary failure in name resolution',))\n",
      "Exception in thread Thread-9:\n",
      "Traceback (most recent call last):\n",
      "  File \"/usr/lib/python2.7/threading.py\", line 801, in __bootstrap_inner\n",
      "    self.run()\n",
      "  File \"/usr/lib/python2.7/threading.py\", line 754, in run\n",
      "    self.__target(*self.__args, **self.__kwargs)\n",
      "  File \"<ipython-input-1-a7b5dcdf2c63>\", line 43, in threader\n",
      "    get_data(m[0],m[1],m[2],m[3])\n",
      "  File \"<ipython-input-1-a7b5dcdf2c63>\", line 11, in get_data\n",
      "    urlData = requests.get(url).content\n",
      "  File \"/usr/local/lib/python2.7/dist-packages/requests/api.py\", line 72, in get\n",
      "    return request('get', url, params=params, **kwargs)\n",
      "  File \"/usr/local/lib/python2.7/dist-packages/requests/api.py\", line 58, in request\n",
      "    return session.request(method=method, url=url, **kwargs)\n",
      "  File \"/usr/local/lib/python2.7/dist-packages/requests/sessions.py\", line 508, in request\n",
      "    resp = self.send(prep, **send_kwargs)\n",
      "  File \"/usr/local/lib/python2.7/dist-packages/requests/sessions.py\", line 618, in send\n",
      "    r = adapter.send(request, **kwargs)\n",
      "  File \"/usr/local/lib/python2.7/dist-packages/requests/adapters.py\", line 508, in send\n",
      "    raise ConnectionError(e, request=request)\n",
      "ConnectionError: HTTPConnectionPool(host='weather.uwyo.edu', port=80): Max retries exceeded with url: /cgi-bin/sounding?region=naconf&TYPE=TEXT%3ALIST&YEAR=2007&MONTH=7&FROM=200&TO=200&STNM=16080 (Caused by NewConnectionError('<urllib3.connection.HTTPConnection object at 0x7f749c126a50>: Failed to establish a new connection: [Errno -3] Temporary failure in name resolution',))\n",
      "Exception in thread Thread-21:\n",
      "Traceback (most recent call last):\n",
      "  File \"/usr/lib/python2.7/threading.py\", line 801, in __bootstrap_inner\n",
      "    self.run()\n",
      "  File \"/usr/lib/python2.7/threading.py\", line 754, in run\n",
      "    self.__target(*self.__args, **self.__kwargs)\n",
      "  File \"<ipython-input-1-a7b5dcdf2c63>\", line 43, in threader\n",
      "    get_data(m[0],m[1],m[2],m[3])\n",
      "  File \"<ipython-input-1-a7b5dcdf2c63>\", line 11, in get_data\n",
      "    urlData = requests.get(url).content\n",
      "  File \"/usr/local/lib/python2.7/dist-packages/requests/api.py\", line 72, in get\n",
      "    return request('get', url, params=params, **kwargs)\n",
      "  File \"/usr/local/lib/python2.7/dist-packages/requests/api.py\", line 58, in request\n",
      "    return session.request(method=method, url=url, **kwargs)\n",
      "  File \"/usr/local/lib/python2.7/dist-packages/requests/sessions.py\", line 508, in request\n",
      "    resp = self.send(prep, **send_kwargs)\n",
      "  File \"/usr/local/lib/python2.7/dist-packages/requests/sessions.py\", line 618, in send\n",
      "    r = adapter.send(request, **kwargs)\n",
      "  File \"/usr/local/lib/python2.7/dist-packages/requests/adapters.py\", line 508, in send\n",
      "    raise ConnectionError(e, request=request)\n",
      "ConnectionError: HTTPConnectionPool(host='weather.uwyo.edu', port=80): Max retries exceeded with url: /cgi-bin/sounding?region=naconf&TYPE=TEXT%3ALIST&YEAR=2007&MONTH=7&FROM=600&TO=600&STNM=16080 (Caused by NewConnectionError('<urllib3.connection.HTTPConnection object at 0x7f747c0d2f10>: Failed to establish a new connection: [Errno -3] Temporary failure in name resolution',))\n",
      "Exception in thread Thread-7:\n",
      "Traceback (most recent call last):\n",
      "  File \"/usr/lib/python2.7/threading.py\", line 801, in __bootstrap_inner\n",
      "    self.run()\n",
      "  File \"/usr/lib/python2.7/threading.py\", line 754, in run\n",
      "    self.__target(*self.__args, **self.__kwargs)\n",
      "  File \"<ipython-input-1-a7b5dcdf2c63>\", line 43, in threader\n",
      "    get_data(m[0],m[1],m[2],m[3])\n",
      "  File \"<ipython-input-1-a7b5dcdf2c63>\", line 11, in get_data\n",
      "    urlData = requests.get(url).content\n",
      "  File \"/usr/local/lib/python2.7/dist-packages/requests/api.py\", line 72, in get\n",
      "    return request('get', url, params=params, **kwargs)\n",
      "  File \"/usr/local/lib/python2.7/dist-packages/requests/api.py\", line 58, in request\n",
      "    return session.request(method=method, url=url, **kwargs)\n",
      "  File \"/usr/local/lib/python2.7/dist-packages/requests/sessions.py\", line 508, in request\n",
      "    resp = self.send(prep, **send_kwargs)\n",
      "  File \"/usr/local/lib/python2.7/dist-packages/requests/sessions.py\", line 618, in send\n",
      "    r = adapter.send(request, **kwargs)\n",
      "  File \"/usr/local/lib/python2.7/dist-packages/requests/adapters.py\", line 508, in send\n",
      "    raise ConnectionError(e, request=request)\n",
      "ConnectionError: HTTPConnectionPool(host='weather.uwyo.edu', port=80): Max retries exceeded with url: /cgi-bin/sounding?region=naconf&TYPE=TEXT%3ALIST&YEAR=2007&MONTH=7&FROM=700&TO=700&STNM=16080 (Caused by NewConnectionError('<urllib3.connection.HTTPConnection object at 0x7f747c0d27d0>: Failed to establish a new connection: [Errno -3] Temporary failure in name resolution',))\n",
      "\n",
      "\n",
      "\n",
      "\n"
     ]
    },
    {
     "name": "stderr",
     "output_type": "stream",
     "text": [
      "Exception in thread Thread-32:\n",
      "Traceback (most recent call last):\n",
      "  File \"/usr/lib/python2.7/threading.py\", line 801, in __bootstrap_inner\n",
      "    self.run()\n",
      "  File \"/usr/lib/python2.7/threading.py\", line 754, in run\n",
      "    self.__target(*self.__args, **self.__kwargs)\n",
      "  File \"<ipython-input-1-a7b5dcdf2c63>\", line 43, in threader\n",
      "    get_data(m[0],m[1],m[2],m[3])\n",
      "  File \"<ipython-input-1-a7b5dcdf2c63>\", line 11, in get_data\n",
      "    urlData = requests.get(url).content\n",
      "  File \"/usr/local/lib/python2.7/dist-packages/requests/api.py\", line 72, in get\n",
      "    return request('get', url, params=params, **kwargs)\n",
      "  File \"/usr/local/lib/python2.7/dist-packages/requests/api.py\", line 58, in request\n",
      "    return session.request(method=method, url=url, **kwargs)\n",
      "  File \"/usr/local/lib/python2.7/dist-packages/requests/sessions.py\", line 508, in request\n",
      "    resp = self.send(prep, **send_kwargs)\n",
      "  File \"/usr/local/lib/python2.7/dist-packages/requests/sessions.py\", line 618, in send\n",
      "    r = adapter.send(request, **kwargs)\n",
      "  File \"/usr/local/lib/python2.7/dist-packages/requests/adapters.py\", line 508, in send\n",
      "    raise ConnectionError(e, request=request)\n",
      "ConnectionError: HTTPConnectionPool(host='weather.uwyo.edu', port=80): Max retries exceeded with url: /cgi-bin/sounding?region=naconf&TYPE=TEXT%3ALIST&YEAR=2007&MONTH=7&FROM=1200&TO=1200&STNM=16080 (Caused by NewConnectionError('<urllib3.connection.HTTPConnection object at 0x7f747c1110d0>: Failed to establish a new connection: [Errno -3] Temporary failure in name resolution',))\n",
      "Exception in thread Thread-52:\n",
      "Traceback (most recent call last):\n",
      "  File \"/usr/lib/python2.7/threading.py\", line 801, in __bootstrap_inner\n",
      "    self.run()\n",
      "  File \"/usr/lib/python2.7/threading.py\", line 754, in run\n",
      "    self.__target(*self.__args, **self.__kwargs)\n",
      "  File \"<ipython-input-1-a7b5dcdf2c63>\", line 43, in threader\n",
      "    get_data(m[0],m[1],m[2],m[3])\n",
      "  File \"<ipython-input-1-a7b5dcdf2c63>\", line 11, in get_data\n",
      "    urlData = requests.get(url).content\n",
      "  File \"/usr/local/lib/python2.7/dist-packages/requests/api.py\", line 72, in get\n",
      "    return request('get', url, params=params, **kwargs)\n",
      "  File \"/usr/local/lib/python2.7/dist-packages/requests/api.py\", line 58, in request\n",
      "    return session.request(method=method, url=url, **kwargs)\n",
      "  File \"/usr/local/lib/python2.7/dist-packages/requests/sessions.py\", line 508, in request\n",
      "    resp = self.send(prep, **send_kwargs)\n",
      "  File \"/usr/local/lib/python2.7/dist-packages/requests/sessions.py\", line 618, in send\n",
      "    r = adapter.send(request, **kwargs)\n",
      "  File \"/usr/local/lib/python2.7/dist-packages/requests/adapters.py\", line 508, in send\n",
      "    raise ConnectionError(e, request=request)\n",
      "ConnectionError: HTTPConnectionPool(host='weather.uwyo.edu', port=80): Max retries exceeded with url: /cgi-bin/sounding?region=naconf&TYPE=TEXT%3ALIST&YEAR=2007&MONTH=3&FROM=1400&TO=1400&STNM=16080 (Caused by NewConnectionError('<urllib3.connection.HTTPConnection object at 0x7f747c12c050>: Failed to establish a new connection: [Errno -3] Temporary failure in name resolution',))\n",
      "Exception in thread Thread-46:\n",
      "Traceback (most recent call last):\n",
      "  File \"/usr/lib/python2.7/threading.py\", line 801, in __bootstrap_inner\n",
      "    self.run()\n",
      "  File \"/usr/lib/python2.7/threading.py\", line 754, in run\n",
      "    self.__target(*self.__args, **self.__kwargs)\n",
      "  File \"<ipython-input-1-a7b5dcdf2c63>\", line 43, in threader\n",
      "    get_data(m[0],m[1],m[2],m[3])\n",
      "  File \"<ipython-input-1-a7b5dcdf2c63>\", line 11, in get_data\n",
      "    urlData = requests.get(url).content\n",
      "  File \"/usr/local/lib/python2.7/dist-packages/requests/api.py\", line 72, in get\n",
      "    return request('get', url, params=params, **kwargs)\n",
      "  File \"/usr/local/lib/python2.7/dist-packages/requests/api.py\", line 58, in request\n",
      "    return session.request(method=method, url=url, **kwargs)\n",
      "  File \"/usr/local/lib/python2.7/dist-packages/requests/sessions.py\", line 508, in request\n",
      "    resp = self.send(prep, **send_kwargs)\n",
      "  File \"/usr/local/lib/python2.7/dist-packages/requests/sessions.py\", line 618, in send\n",
      "    r = adapter.send(request, **kwargs)\n",
      "  File \"/usr/local/lib/python2.7/dist-packages/requests/adapters.py\", line 508, in send\n",
      "    raise ConnectionError(e, request=request)\n",
      "ConnectionError: HTTPConnectionPool(host='weather.uwyo.edu', port=80): Max retries exceeded with url: /cgi-bin/sounding?region=naconf&TYPE=TEXT%3ALIST&YEAR=2007&MONTH=3&FROM=900&TO=900&STNM=16080 (Caused by NewConnectionError('<urllib3.connection.HTTPConnection object at 0x7f747c15f810>: Failed to establish a new connection: [Errno -3] Temporary failure in name resolution',))\n",
      "\n",
      "Exception in thread Thread-40:\n",
      "Traceback (most recent call last):\n",
      "  File \"/usr/lib/python2.7/threading.py\", line 801, in __bootstrap_inner\n",
      "    self.run()\n",
      "  File \"/usr/lib/python2.7/threading.py\", line 754, in run\n",
      "    self.__target(*self.__args, **self.__kwargs)\n",
      "  File \"<ipython-input-1-a7b5dcdf2c63>\", line 43, in threader\n",
      "    get_data(m[0],m[1],m[2],m[3])\n",
      "  File \"<ipython-input-1-a7b5dcdf2c63>\", line 11, in get_data\n",
      "    urlData = requests.get(url).content\n",
      "  File \"/usr/local/lib/python2.7/dist-packages/requests/api.py\", line 72, in get\n",
      "    return request('get', url, params=params, **kwargs)\n",
      "  File \"/usr/local/lib/python2.7/dist-packages/requests/api.py\", line 58, in request\n",
      "    return session.request(method=method, url=url, **kwargs)\n",
      "  File \"/usr/local/lib/python2.7/dist-packages/requests/sessions.py\", line 508, in request\n",
      "    resp = self.send(prep, **send_kwargs)\n",
      "  File \"/usr/local/lib/python2.7/dist-packages/requests/sessions.py\", line 618, in send\n",
      "    r = adapter.send(request, **kwargs)\n",
      "  File \"/usr/local/lib/python2.7/dist-packages/requests/adapters.py\", line 508, in send\n",
      "    raise ConnectionError(e, request=request)\n",
      "ConnectionError: HTTPConnectionPool(host='weather.uwyo.edu', port=80): Max retries exceeded with url: /cgi-bin/sounding?region=naconf&TYPE=TEXT%3ALIST&YEAR=2007&MONTH=7&FROM=500&TO=500&STNM=16080 (Caused by NewConnectionError('<urllib3.connection.HTTPConnection object at 0x7f749c126490>: Failed to establish a new connection: [Errno -3] Temporary failure in name resolution',))\n",
      "\n",
      "\n",
      "Exception in thread Thread-27:\n",
      "Traceback (most recent call last):\n",
      "  File \"/usr/lib/python2.7/threading.py\", line 801, in __bootstrap_inner\n",
      "    self.run()\n",
      "  File \"/usr/lib/python2.7/threading.py\", line 754, in run\n",
      "    self.__target(*self.__args, **self.__kwargs)\n",
      "  File \"<ipython-input-1-a7b5dcdf2c63>\", line 43, in threader\n",
      "    get_data(m[0],m[1],m[2],m[3])\n",
      "  File \"<ipython-input-1-a7b5dcdf2c63>\", line 11, in get_data\n",
      "    urlData = requests.get(url).content\n",
      "  File \"/usr/local/lib/python2.7/dist-packages/requests/api.py\", line 72, in get\n",
      "    return request('get', url, params=params, **kwargs)\n",
      "  File \"/usr/local/lib/python2.7/dist-packages/requests/api.py\", line 58, in request\n",
      "    return session.request(method=method, url=url, **kwargs)\n",
      "  File \"/usr/local/lib/python2.7/dist-packages/requests/sessions.py\", line 508, in request\n",
      "    resp = self.send(prep, **send_kwargs)\n",
      "  File \"/usr/local/lib/python2.7/dist-packages/requests/sessions.py\", line 618, in send\n",
      "    r = adapter.send(request, **kwargs)\n",
      "  File \"/usr/local/lib/python2.7/dist-packages/requests/adapters.py\", line 508, in send\n",
      "    raise ConnectionError(e, request=request)\n",
      "ConnectionError: HTTPConnectionPool(host='weather.uwyo.edu', port=80): Max retries exceeded with url: /cgi-bin/sounding?region=naconf&TYPE=TEXT%3ALIST&YEAR=2007&MONTH=6&FROM=3100&TO=3100&STNM=16080 (Caused by NewConnectionError('<urllib3.connection.HTTPConnection object at 0x7f749c099cd0>: Failed to establish a new connection: [Errno -3] Temporary failure in name resolution',))\n",
      "\n",
      "Exception in thread Thread-26:\n",
      "Traceback (most recent call last):\n",
      "  File \"/usr/lib/python2.7/threading.py\", line 801, in __bootstrap_inner\n",
      "    self.run()\n",
      "  File \"/usr/lib/python2.7/threading.py\", line 754, in run\n",
      "    self.__target(*self.__args, **self.__kwargs)\n",
      "  File \"<ipython-input-1-a7b5dcdf2c63>\", line 43, in threader\n",
      "    get_data(m[0],m[1],m[2],m[3])\n",
      "  File \"<ipython-input-1-a7b5dcdf2c63>\", line 11, in get_data\n",
      "    urlData = requests.get(url).content\n",
      "  File \"/usr/local/lib/python2.7/dist-packages/requests/api.py\", line 72, in get\n",
      "    return request('get', url, params=params, **kwargs)\n",
      "  File \"/usr/local/lib/python2.7/dist-packages/requests/api.py\", line 58, in request\n",
      "    return session.request(method=method, url=url, **kwargs)\n",
      "  File \"/usr/local/lib/python2.7/dist-packages/requests/sessions.py\", line 508, in request\n",
      "    resp = self.send(prep, **send_kwargs)\n",
      "  File \"/usr/local/lib/python2.7/dist-packages/requests/sessions.py\", line 618, in send\n",
      "    r = adapter.send(request, **kwargs)\n",
      "  File \"/usr/local/lib/python2.7/dist-packages/requests/adapters.py\", line 508, in send\n",
      "    raise ConnectionError(e, request=request)\n",
      "ConnectionError: HTTPConnectionPool(host='weather.uwyo.edu', port=80): Max retries exceeded with url: /cgi-bin/sounding?region=naconf&TYPE=TEXT%3ALIST&YEAR=2007&MONTH=7&FROM=1700&TO=1700&STNM=16080 (Caused by NewConnectionError('<urllib3.connection.HTTPConnection object at 0x7f749c05fa90>: Failed to establish a new connection: [Errno -3] Temporary failure in name resolution',))\n",
      "Exception in thread Thread-14:\n",
      "Traceback (most recent call last):\n",
      "  File \"/usr/lib/python2.7/threading.py\", line 801, in __bootstrap_inner\n",
      "    self.run()\n",
      "  File \"/usr/lib/python2.7/threading.py\", line 754, in run\n",
      "    self.__target(*self.__args, **self.__kwargs)\n",
      "  File \"<ipython-input-1-a7b5dcdf2c63>\", line 43, in threader\n",
      "    get_data(m[0],m[1],m[2],m[3])\n",
      "  File \"<ipython-input-1-a7b5dcdf2c63>\", line 11, in get_data\n",
      "    urlData = requests.get(url).content\n",
      "  File \"/usr/local/lib/python2.7/dist-packages/requests/api.py\", line 72, in get\n",
      "    return request('get', url, params=params, **kwargs)\n",
      "  File \"/usr/local/lib/python2.7/dist-packages/requests/api.py\", line 58, in request\n",
      "    return session.request(method=method, url=url, **kwargs)\n",
      "  File \"/usr/local/lib/python2.7/dist-packages/requests/sessions.py\", line 508, in request\n",
      "    resp = self.send(prep, **send_kwargs)\n",
      "  File \"/usr/local/lib/python2.7/dist-packages/requests/sessions.py\", line 618, in send\n",
      "    r = adapter.send(request, **kwargs)\n",
      "  File \"/usr/local/lib/python2.7/dist-packages/requests/adapters.py\", line 508, in send\n",
      "    raise ConnectionError(e, request=request)\n",
      "ConnectionError: HTTPConnectionPool(host='weather.uwyo.edu', port=80): Max retries exceeded with url: /cgi-bin/sounding?region=naconf&TYPE=TEXT%3ALIST&YEAR=2007&MONTH=7&FROM=1300&TO=1300&STNM=16080 (Caused by NewConnectionError('<urllib3.connection.HTTPConnection object at 0x7f747c1a8e10>: Failed to establish a new connection: [Errno -3] Temporary failure in name resolution',))\n",
      "\n",
      "Exception in thread Thread-36:\n",
      "Traceback (most recent call last):\n",
      "  File \"/usr/lib/python2.7/threading.py\", line 801, in __bootstrap_inner\n",
      "    self.run()\n",
      "  File \"/usr/lib/python2.7/threading.py\", line 754, in run\n",
      "    self.__target(*self.__args, **self.__kwargs)\n",
      "  File \"<ipython-input-1-a7b5dcdf2c63>\", line 43, in threader\n",
      "    get_data(m[0],m[1],m[2],m[3])\n",
      "  File \"<ipython-input-1-a7b5dcdf2c63>\", line 11, in get_data\n",
      "    urlData = requests.get(url).content\n",
      "  File \"/usr/local/lib/python2.7/dist-packages/requests/api.py\", line 72, in get\n",
      "    return request('get', url, params=params, **kwargs)\n",
      "  File \"/usr/local/lib/python2.7/dist-packages/requests/api.py\", line 58, in request\n",
      "    return session.request(method=method, url=url, **kwargs)\n",
      "  File \"/usr/local/lib/python2.7/dist-packages/requests/sessions.py\", line 508, in request\n",
      "    resp = self.send(prep, **send_kwargs)\n",
      "  File \"/usr/local/lib/python2.7/dist-packages/requests/sessions.py\", line 618, in send\n",
      "    r = adapter.send(request, **kwargs)\n",
      "  File \"/usr/local/lib/python2.7/dist-packages/requests/adapters.py\", line 508, in send\n",
      "    raise ConnectionError(e, request=request)\n",
      "ConnectionError: HTTPConnectionPool(host='weather.uwyo.edu', port=80): Max retries exceeded with url: /cgi-bin/sounding?region=naconf&TYPE=TEXT%3ALIST&YEAR=2007&MONTH=3&FROM=1100&TO=1100&STNM=16080 (Caused by NewConnectionError('<urllib3.connection.HTTPConnection object at 0x7f749c027750>: Failed to establish a new connection: [Errno -3] Temporary failure in name resolution',))\n",
      "\n",
      "\n",
      "\n",
      "Exception in thread Thread-25:\n",
      "Traceback (most recent call last):\n",
      "  File \"/usr/lib/python2.7/threading.py\", line 801, in __bootstrap_inner\n",
      "    self.run()\n",
      "  File \"/usr/lib/python2.7/threading.py\", line 754, in run\n",
      "    self.__target(*self.__args, **self.__kwargs)\n",
      "  File \"<ipython-input-1-a7b5dcdf2c63>\", line 43, in threader\n",
      "    get_data(m[0],m[1],m[2],m[3])\n",
      "  File \"<ipython-input-1-a7b5dcdf2c63>\", line 11, in get_data\n",
      "    urlData = requests.get(url).content\n",
      "  File \"/usr/local/lib/python2.7/dist-packages/requests/api.py\", line 72, in get\n",
      "    return request('get', url, params=params, **kwargs)\n",
      "  File \"/usr/local/lib/python2.7/dist-packages/requests/api.py\", line 58, in request\n",
      "    return session.request(method=method, url=url, **kwargs)\n",
      "  File \"/usr/local/lib/python2.7/dist-packages/requests/sessions.py\", line 508, in request\n",
      "    resp = self.send(prep, **send_kwargs)\n",
      "  File \"/usr/local/lib/python2.7/dist-packages/requests/sessions.py\", line 618, in send\n",
      "    r = adapter.send(request, **kwargs)\n",
      "  File \"/usr/local/lib/python2.7/dist-packages/requests/adapters.py\", line 508, in send\n",
      "    raise ConnectionError(e, request=request)\n",
      "ConnectionError: HTTPConnectionPool(host='weather.uwyo.edu', port=80): Max retries exceeded with url: /cgi-bin/sounding?region=naconf&TYPE=TEXT%3ALIST&YEAR=2007&MONTH=6&FROM=300&TO=300&STNM=16080 (Caused by NewConnectionError('<urllib3.connection.HTTPConnection object at 0x7f749c0abe10>: Failed to establish a new connection: [Errno -3] Temporary failure in name resolution',))\n",
      "\n",
      "Exception in thread Thread-38:\n",
      "Traceback (most recent call last):\n",
      "  File \"/usr/lib/python2.7/threading.py\", line 801, in __bootstrap_inner\n",
      "    self.run()\n",
      "  File \"/usr/lib/python2.7/threading.py\", line 754, in run\n",
      "    self.__target(*self.__args, **self.__kwargs)\n",
      "  File \"<ipython-input-1-a7b5dcdf2c63>\", line 43, in threader\n",
      "    get_data(m[0],m[1],m[2],m[3])\n",
      "  File \"<ipython-input-1-a7b5dcdf2c63>\", line 11, in get_data\n",
      "    urlData = requests.get(url).content\n",
      "  File \"/usr/local/lib/python2.7/dist-packages/requests/api.py\", line 72, in get\n",
      "    return request('get', url, params=params, **kwargs)\n",
      "  File \"/usr/local/lib/python2.7/dist-packages/requests/api.py\", line 58, in request\n",
      "    return session.request(method=method, url=url, **kwargs)\n",
      "  File \"/usr/local/lib/python2.7/dist-packages/requests/sessions.py\", line 508, in request\n",
      "    resp = self.send(prep, **send_kwargs)\n",
      "  File \"/usr/local/lib/python2.7/dist-packages/requests/sessions.py\", line 618, in send\n",
      "    r = adapter.send(request, **kwargs)\n",
      "  File \"/usr/local/lib/python2.7/dist-packages/requests/adapters.py\", line 508, in send\n",
      "    raise ConnectionError(e, request=request)\n",
      "ConnectionError: HTTPConnectionPool(host='weather.uwyo.edu', port=80): Max retries exceeded with url: /cgi-bin/sounding?region=naconf&TYPE=TEXT%3ALIST&YEAR=2007&MONTH=7&FROM=1600&TO=1600&STNM=16080 (Caused by NewConnectionError('<urllib3.connection.HTTPConnection object at 0x7f749c10c350>: Failed to establish a new connection: [Errno -3] Temporary failure in name resolution',))\n",
      "\n"
     ]
    },
    {
     "name": "stderr",
     "output_type": "stream",
     "text": [
      "Exception in thread Thread-50:\n",
      "Traceback (most recent call last):\n",
      "  File \"/usr/lib/python2.7/threading.py\", line 801, in __bootstrap_inner\n",
      "    self.run()\n",
      "  File \"/usr/lib/python2.7/threading.py\", line 754, in run\n",
      "    self.__target(*self.__args, **self.__kwargs)\n",
      "  File \"<ipython-input-1-a7b5dcdf2c63>\", line 43, in threader\n",
      "    get_data(m[0],m[1],m[2],m[3])\n",
      "  File \"<ipython-input-1-a7b5dcdf2c63>\", line 11, in get_data\n",
      "    urlData = requests.get(url).content\n",
      "  File \"/usr/local/lib/python2.7/dist-packages/requests/api.py\", line 72, in get\n",
      "    return request('get', url, params=params, **kwargs)\n",
      "  File \"/usr/local/lib/python2.7/dist-packages/requests/api.py\", line 58, in request\n",
      "    return session.request(method=method, url=url, **kwargs)\n",
      "  File \"/usr/local/lib/python2.7/dist-packages/requests/sessions.py\", line 508, in request\n",
      "    resp = self.send(prep, **send_kwargs)\n",
      "  File \"/usr/local/lib/python2.7/dist-packages/requests/sessions.py\", line 618, in send\n",
      "    r = adapter.send(request, **kwargs)\n",
      "  File \"/usr/local/lib/python2.7/dist-packages/requests/adapters.py\", line 508, in send\n",
      "    raise ConnectionError(e, request=request)\n",
      "ConnectionError: HTTPConnectionPool(host='weather.uwyo.edu', port=80): Max retries exceeded with url: /cgi-bin/sounding?region=naconf&TYPE=TEXT%3ALIST&YEAR=2007&MONTH=8&FROM=2200&TO=2200&STNM=16080 (Caused by NewConnectionError('<urllib3.connection.HTTPConnection object at 0x7f749c016810>: Failed to establish a new connection: [Errno -3] Temporary failure in name resolution',))\n",
      "\n",
      "Exception in thread Thread-20:\n",
      "Traceback (most recent call last):\n",
      "  File \"/usr/lib/python2.7/threading.py\", line 801, in __bootstrap_inner\n",
      "    self.run()\n",
      "  File \"/usr/lib/python2.7/threading.py\", line 754, in run\n",
      "    self.__target(*self.__args, **self.__kwargs)\n",
      "  File \"<ipython-input-1-a7b5dcdf2c63>\", line 43, in threader\n",
      "    get_data(m[0],m[1],m[2],m[3])\n",
      "  File \"<ipython-input-1-a7b5dcdf2c63>\", line 11, in get_data\n",
      "    urlData = requests.get(url).content\n",
      "  File \"/usr/local/lib/python2.7/dist-packages/requests/api.py\", line 72, in get\n",
      "    return request('get', url, params=params, **kwargs)\n",
      "  File \"/usr/local/lib/python2.7/dist-packages/requests/api.py\", line 58, in request\n",
      "    return session.request(method=method, url=url, **kwargs)\n",
      "  File \"/usr/local/lib/python2.7/dist-packages/requests/sessions.py\", line 508, in request\n",
      "    resp = self.send(prep, **send_kwargs)\n",
      "  File \"/usr/local/lib/python2.7/dist-packages/requests/sessions.py\", line 618, in send\n",
      "    r = adapter.send(request, **kwargs)\n",
      "  File \"/usr/local/lib/python2.7/dist-packages/requests/adapters.py\", line 508, in send\n",
      "    raise ConnectionError(e, request=request)\n",
      "ConnectionError: HTTPConnectionPool(host='weather.uwyo.edu', port=80): Max retries exceeded with url: /cgi-bin/sounding?region=naconf&TYPE=TEXT%3ALIST&YEAR=2007&MONTH=8&FROM=1300&TO=1300&STNM=16080 (Caused by NewConnectionError('<urllib3.connection.HTTPConnection object at 0x7f749c016390>: Failed to establish a new connection: [Errno -3] Temporary failure in name resolution',))\n",
      "\n",
      "Exception in thread Thread-8:\n",
      "Traceback (most recent call last):\n",
      "  File \"/usr/lib/python2.7/threading.py\", line 801, in __bootstrap_inner\n",
      "    self.run()\n",
      "  File \"/usr/lib/python2.7/threading.py\", line 754, in run\n",
      "    self.__target(*self.__args, **self.__kwargs)\n",
      "  File \"<ipython-input-1-a7b5dcdf2c63>\", line 43, in threader\n",
      "    get_data(m[0],m[1],m[2],m[3])\n",
      "  File \"<ipython-input-1-a7b5dcdf2c63>\", line 11, in get_data\n",
      "    urlData = requests.get(url).content\n",
      "  File \"/usr/local/lib/python2.7/dist-packages/requests/api.py\", line 72, in get\n",
      "    return request('get', url, params=params, **kwargs)\n",
      "  File \"/usr/local/lib/python2.7/dist-packages/requests/api.py\", line 58, in request\n",
      "    return session.request(method=method, url=url, **kwargs)\n",
      "  File \"/usr/local/lib/python2.7/dist-packages/requests/sessions.py\", line 508, in request\n",
      "    resp = self.send(prep, **send_kwargs)\n",
      "  File \"/usr/local/lib/python2.7/dist-packages/requests/sessions.py\", line 618, in send\n",
      "    r = adapter.send(request, **kwargs)\n",
      "  File \"/usr/local/lib/python2.7/dist-packages/requests/adapters.py\", line 508, in send\n",
      "    raise ConnectionError(e, request=request)\n",
      "ConnectionError: HTTPConnectionPool(host='weather.uwyo.edu', port=80): Max retries exceeded with url: /cgi-bin/sounding?region=naconf&TYPE=TEXT%3ALIST&YEAR=2007&MONTH=8&FROM=2500&TO=2500&STNM=16080 (Caused by NewConnectionError('<urllib3.connection.HTTPConnection object at 0x7f749c126ad0>: Failed to establish a new connection: [Errno -3] Temporary failure in name resolution',))\n",
      "\n",
      "Exception in thread Thread-13:\n",
      "Traceback (most recent call last):\n",
      "  File \"/usr/lib/python2.7/threading.py\", line 801, in __bootstrap_inner\n",
      "    self.run()\n",
      "  File \"/usr/lib/python2.7/threading.py\", line 754, in run\n",
      "    self.__target(*self.__args, **self.__kwargs)\n",
      "  File \"<ipython-input-1-a7b5dcdf2c63>\", line 43, in threader\n",
      "    get_data(m[0],m[1],m[2],m[3])\n",
      "  File \"<ipython-input-1-a7b5dcdf2c63>\", line 11, in get_data\n",
      "    urlData = requests.get(url).content\n",
      "  File \"/usr/local/lib/python2.7/dist-packages/requests/api.py\", line 72, in get\n",
      "    return request('get', url, params=params, **kwargs)\n",
      "  File \"/usr/local/lib/python2.7/dist-packages/requests/api.py\", line 58, in request\n",
      "    return session.request(method=method, url=url, **kwargs)\n",
      "  File \"/usr/local/lib/python2.7/dist-packages/requests/sessions.py\", line 508, in request\n",
      "    resp = self.send(prep, **send_kwargs)\n",
      "  File \"/usr/local/lib/python2.7/dist-packages/requests/sessions.py\", line 618, in send\n",
      "    r = adapter.send(request, **kwargs)\n",
      "  File \"/usr/local/lib/python2.7/dist-packages/requests/adapters.py\", line 508, in send\n",
      "    raise ConnectionError(e, request=request)\n",
      "ConnectionError: HTTPConnectionPool(host='weather.uwyo.edu', port=80): Max retries exceeded with url: /cgi-bin/sounding?region=naconf&TYPE=TEXT%3ALIST&YEAR=2007&MONTH=8&FROM=1500&TO=1500&STNM=16080 (Caused by NewConnectionError('<urllib3.connection.HTTPConnection object at 0x7f749c126210>: Failed to establish a new connection: [Errno -3] Temporary failure in name resolution',))\n",
      "\n",
      "Exception in thread Thread-37:\n",
      "Traceback (most recent call last):\n",
      "  File \"/usr/lib/python2.7/threading.py\", line 801, in __bootstrap_inner\n",
      "    self.run()\n",
      "  File \"/usr/lib/python2.7/threading.py\", line 754, in run\n",
      "    self.__target(*self.__args, **self.__kwargs)\n",
      "  File \"<ipython-input-1-a7b5dcdf2c63>\", line 43, in threader\n",
      "    get_data(m[0],m[1],m[2],m[3])\n",
      "  File \"<ipython-input-1-a7b5dcdf2c63>\", line 11, in get_data\n",
      "    urlData = requests.get(url).content\n",
      "  File \"/usr/local/lib/python2.7/dist-packages/requests/api.py\", line 72, in get\n",
      "    return request('get', url, params=params, **kwargs)\n",
      "  File \"/usr/local/lib/python2.7/dist-packages/requests/api.py\", line 58, in request\n",
      "    return session.request(method=method, url=url, **kwargs)\n",
      "  File \"/usr/local/lib/python2.7/dist-packages/requests/sessions.py\", line 508, in request\n",
      "    resp = self.send(prep, **send_kwargs)\n",
      "  File \"/usr/local/lib/python2.7/dist-packages/requests/sessions.py\", line 618, in send\n",
      "    r = adapter.send(request, **kwargs)\n",
      "  File \"/usr/local/lib/python2.7/dist-packages/requests/adapters.py\", line 508, in send\n",
      "    raise ConnectionError(e, request=request)\n",
      "ConnectionError: HTTPConnectionPool(host='weather.uwyo.edu', port=80): Max retries exceeded with url: /cgi-bin/sounding?region=naconf&TYPE=TEXT%3ALIST&YEAR=2008&MONTH=6&FROM=2700&TO=2700&STNM=16080 (Caused by NewConnectionError('<urllib3.connection.HTTPConnection object at 0x7f749e968b90>: Failed to establish a new connection: [Errno -3] Temporary failure in name resolution',))\n",
      "\n",
      "Exception in thread Thread-19:\n",
      "Traceback (most recent call last):\n",
      "  File \"/usr/lib/python2.7/threading.py\", line 801, in __bootstrap_inner\n",
      "    self.run()\n",
      "  File \"/usr/lib/python2.7/threading.py\", line 754, in run\n",
      "    self.__target(*self.__args, **self.__kwargs)\n",
      "  File \"<ipython-input-1-a7b5dcdf2c63>\", line 43, in threader\n",
      "    get_data(m[0],m[1],m[2],m[3])\n",
      "  File \"<ipython-input-1-a7b5dcdf2c63>\", line 11, in get_data\n",
      "    urlData = requests.get(url).content\n",
      "  File \"/usr/local/lib/python2.7/dist-packages/requests/api.py\", line 72, in get\n",
      "    return request('get', url, params=params, **kwargs)\n",
      "  File \"/usr/local/lib/python2.7/dist-packages/requests/api.py\", line 58, in request\n",
      "    return session.request(method=method, url=url, **kwargs)\n",
      "  File \"/usr/local/lib/python2.7/dist-packages/requests/sessions.py\", line 508, in request\n",
      "    resp = self.send(prep, **send_kwargs)\n",
      "  File \"/usr/local/lib/python2.7/dist-packages/requests/sessions.py\", line 618, in send\n",
      "    r = adapter.send(request, **kwargs)\n",
      "  File \"/usr/local/lib/python2.7/dist-packages/requests/adapters.py\", line 508, in send\n",
      "    raise ConnectionError(e, request=request)\n",
      "ConnectionError: HTTPConnectionPool(host='weather.uwyo.edu', port=80): Max retries exceeded with url: /cgi-bin/sounding?region=naconf&TYPE=TEXT%3ALIST&YEAR=2008&MONTH=10&FROM=2300&TO=2300&STNM=16080 (Caused by NewConnectionError('<urllib3.connection.HTTPConnection object at 0x7f747c12cf90>: Failed to establish a new connection: [Errno -3] Temporary failure in name resolution',))\n",
      "\n"
     ]
    }
   ],
   "source": [
    "import pandas as pd\n",
    "import requests\n",
    "from bs4 import BeautifulSoup\n",
    "import re\n",
    "import threading\n",
    "import time\n",
    "from queue import Queue\n",
    "stations = ['16080', '07145', '10739', '10868', '06610']\n",
    "def get_data(station,year,month,date):\n",
    "    url = 'http://weather.uwyo.edu/cgi-bin/sounding?region=naconf&TYPE=TEXT%3ALIST&YEAR='+str(year)+'&MONTH='+str(month)+'&FROM='+str(date)+'00&TO='+str(date)+'00&STNM='+str(station)\n",
    "    path = 'weather/'+str(station)+'_'+str(year)+'_'+str(month)+'_'+str(date)+'.txt'\n",
    "    if(os.path.isfile(path)):\n",
    "        print('file exists',path)\n",
    "        return \n",
    "    while(True):\n",
    "        try:\n",
    "            urlData = requests.get(url).content\n",
    "    #     soup = BeautifulSoup(urlData,\"lxml\")\n",
    "\n",
    "    #         table = soup.find(\"pre\").find(text=True)\n",
    "            \n",
    "            if(\"Invalid TIME parameter.\" not in urlData):\n",
    "                f = open(path,'w+')\n",
    "                f.write(urlData)\n",
    "                f.close()\n",
    "            break\n",
    "        except Exception as  e:\n",
    "            print e\n",
    "\n",
    "print_lock = threading.Lock()\n",
    "\n",
    "q = Queue()\n",
    "# the job whcich we want to perform\n",
    "def job(worker):\n",
    "    time.sleep(1)\n",
    "    i = 0\n",
    "#     for station in stations:\n",
    "#         for year in range(2007,2008):\n",
    "#             for month in range(1,2):\n",
    "#                 for date in range(1,32):\n",
    "#                     get_data(station,year=2010,month,date)\n",
    "            \n",
    "    \n",
    "\n",
    "# creating threader\n",
    "def threader():\n",
    "    while True:\n",
    "        m = q.get()\n",
    "#         job(m)\n",
    "#         print(m[0])\n",
    "        get_data(m[0],m[1],m[2],m[3])\n",
    "        q.task_done()\n",
    "\n",
    "# creating no of thread which we wnt to perform\n",
    "for x in range(50): # example 10 thread\n",
    "    t = threading.Thread(target = threader)\n",
    "    t.daemon = True\n",
    "    t.start()\n",
    "\n",
    "start_time = time.time()\n",
    "\n",
    "#no of tasks which we want to perform\n",
    "# for worker in range(1):\n",
    "#     q.put(worker)\n",
    "for station in stations:\n",
    "    for year in range(2007,2009):\n",
    "        for month in range(1,13):\n",
    "            for date in range(1,32):\n",
    "                q.put([station,year,month,date])\n",
    "        \n",
    "\n",
    "q.join()\n",
    "# for x in range(5):\n",
    "#     print(q[x])\n",
    "\n",
    "print('whole task complete in :',time.time() - start_time)\n",
    "\n",
    "\n",
    "# %time get_data(stations[0],2015,2,31)"
   ]
  },
  {
   "cell_type": "code",
   "execution_count": 12,
   "metadata": {},
   "outputs": [],
   "source": []
  }
 ],
 "metadata": {
  "kernelspec": {
   "display_name": "Python 2",
   "language": "python",
   "name": "python2"
  },
  "language_info": {
   "codemirror_mode": {
    "name": "ipython",
    "version": 2
   },
   "file_extension": ".py",
   "mimetype": "text/x-python",
   "name": "python",
   "nbconvert_exporter": "python",
   "pygments_lexer": "ipython2",
   "version": "2.7.12"
  }
 },
 "nbformat": 4,
 "nbformat_minor": 2
}
